
        <mujoco model="handwriting_robot">
          <option timestep="0.001" gravity="0 0 -9.81"/>
          
          <asset>
            <texture name="grid" type="2d" builtin="checker" rgb1=".1 .2 .3" rgb2=".2 .3 .4" width="300" height="300"/>
            <material name="grid" texture="grid" texrepeat="1 1" reflectance=".2"/>
          </asset>
          
          <worldbody>
            <!-- Ground plane -->
            <geom name="ground" type="plane" size="2 2 .1" material="grid"/>
            
            <!-- Paper surface -->
            <body name="paper" pos="0.5 0 0.01">
              <geom name="paper_geom" type="box" size="0.105 0.148 0.001" rgba="1 1 1 1"/>
            </body>
            
            <!-- Robot base -->
            <body name="robot_base" pos="0 0 0.1">
              <geom name="base_geom" type="cylinder" size="0.05 0.05" rgba="0.5 0.5 0.5 1"/>
              
              <!-- Robot arm link 1 -->
              <body name="link1" pos="0 0 0.05">
                <joint name="joint1" type="hinge" axis="0 0 1" range="-180 180"/>
                <geom name="link1_geom" type="cylinder" size="0.02 0.2" rgba="0.7 0.3 0.3 1"/>
                
                <!-- Robot arm link 2 -->
                <body name="link2" pos="0 0 0.2">
                  <joint name="joint2" type="hinge" axis="1 0 0" range="-90 90"/>
                  <geom name="link2_geom" type="cylinder" size="0.015 0.15" rgba="0.3 0.7 0.3 1"/>
                  
                  <!-- Pen end-effector -->
                  <body name="pen" pos="0 0 0.15">
                    <joint name="pen_joint" type="free"/>
                    <geom name="pen_geom" type="cylinder" size="0.002 0.075" rgba="0 0 1 1"/>
                  </body>
                </body>
              </body>
            </body>
          </worldbody>
          
          <actuator>
            <motor name="motor1" joint="joint1" gear="1"/>
            <motor name="motor2" joint="joint2" gear="1"/>
          </actuator>
        </mujoco>
        